I'm sorry, but an uncaught exception occurred.

While running game code:
  File "game/script.rpy", line 181, in script
    class_rep "Hey, looks like the food square is busy today. You getting anything?"
Exception: Sayer 'class_rep' is not defined.

-- Full Traceback ------------------------------------------------------------

Full traceback:
  File "game/script.rpy", line 181, in script
    class_rep "Hey, looks like the food square is busy today. You getting anything?"
  File "C:\Ren'Py\renpy-8.3.2-sdk\renpy\ast.py", line 2573, in execute
    Say.execute(self)
  File "C:\Ren'Py\renpy-8.3.2-sdk\renpy\ast.py", line 575, in execute
    who = eval_who(self.who, self.who_fast)
  File "C:\Ren'Py\renpy-8.3.2-sdk\renpy\ast.py", line 464, in eval_who
    raise Exception("Sayer '%s' is not defined." % who)
Exception: Sayer 'class_rep' is not defined.

Windows-10-10.0.22631 AMD64
Ren'Py 8.3.2.24090902
Fragmented Connections 1.0
Mon Dec 16 08:23:33 2024
